I'm sorry, but an uncaught exception occurred.

While running game code:
  File "game/script.rpy", line 40, in script
    V "HERO, you ghastly technophobe!"
Exception: Sayer 'V' is not defined.

-- Full Traceback ------------------------------------------------------------

Full traceback:
  File "game/script.rpy", line 40, in script
    V "HERO, you ghastly technophobe!"
  File "C:\Users\Melmiou\Desktop\renpy-8.3.7-sdk\renpy\ast.py", line 2586, in execute
    Say.execute(self)
  File "C:\Users\Melmiou\Desktop\renpy-8.3.7-sdk\renpy\ast.py", line 583, in execute
    who = eval_who(self.who, self.who_fast)
  File "C:\Users\Melmiou\Desktop\renpy-8.3.7-sdk\renpy\ast.py", line 472, in eval_who
    raise Exception("Sayer '%s' is not defined." % who)
Exception: Sayer 'V' is not defined.

Windows-10-10.0.22631 AMD64
Ren'Py 8.3.7.25031702
Athena Awards VN 1.0
Wed Jul 23 03:13:20 2025
